Workbook

Sheet 9
A1: Psalm Pilot | B1: Jason Creasey
A2: Da Roots | B2: Mind Reflection
A3: Coming out | B3: Playmaker feat Robin
A4: Boogie Down | B4: Inurvise
A5: Tribal Style
A6: Romeo & Juliet
A7: Save the last dance for me
A8: Birdie
A9: Licky licky
A10: Remember december
A11: Message | B11: NiNi
A12: Pandemonium
A13: Solina
A14: Typical tropical
A15: Crazy | B15: Dj Doo
A16: Ize Pie
A17: Dr Doolittle | B17: Bambee
A18: The Game | B18: Crispy
A19: Hip Hop Jam
A20: Lemmings on the run
A21: This is rockn roll
A22: We know what to do
A23: Fly away
A24: No princess | B24: Lynn
A25: Little kitty mine
A26: TechLo
A27: Bubble Dancer
A28: Journey
A29: Kiss me
A30: Wham bam boogie
A31: Kiss me red
A32: Burning me up
A33: The deep unknown
A34: Tough enough
A35: Life of a butterfly
A36: How do you do
... A86: Centerfold
A87: 22
A88: Dabbi Doo
A89: Koko Soko
...

Sheet 10
A1: Tricky Disco
A2: Tribal Style
A3: Remember december
A4: Kagami
A5: Calendar Girl
A6: Hybrid | B6: Machinae Supremacy
A7: My Favourite game
A8: Tetris
A9: Get Up
A10: Wanna do
A11: Bells of avalon
A12: Temple of boom
A13: Cryosleep
A14: Fleadh Uncut
A15: Sweet world
A16: Hand of time
A17: Popcorn
A18: Shooting star
... A84: Upular

Sheet 11
A1: 16th stamina test
A2: Charlene
A3: Tears in May
A4: Popular
A5: Johanna shut up
A6: Stunt flying
A7: Children 130
A8: Children 120
A9: Cow Girl
A10: Adventures of Bob on Extacy
A11: Xhosa
A12: Allez ola ole
... A22: Color of the Game

Sheet 12-13
A1: Children
A2: Omnibus
A3: Adagio for strings
A4: Uber Rave 140
A5: In the hall of the mountain King
A6: Elements of Life
A7: Sic Fic
A8: Brave new world
A9: Sands of Evolution
A10: A life so changed
A11: Welcome to the rainbow
A12: Emerge
... A22: The other side

Sheet Danslista
A1: Dansförslag | D1: Tryck fn+F9 för ny danslista
J2: 9
B3: 9 | D3: 10 | F3: 11 | H3: 12-13
B4: =INDEX('9'!$A$1:$A$118,RANDBETWEEN(1,ROWS($A$1:$A$118)),1) -> The last kiss | D4: =INDEX('10'!$A$1:$A$84,RANDBETWEEN(2,ROWS('10'!$A$1:$A$84)),1) -> Calcutta | F4: =INDEX('11'!$A$1:$A$22,RANDBETWEEN(1,ROWS('11'!A1:A22)),1) -> Popular | H4: =INDEX('12-13'!$A$1:$A$22,RANDBETWEEN(1,ROWS('12-13'!$A$1:$A$22)),1) -> Garden State
B5: =INDEX('9'!$A$1:$A$118,RANDBETWEEN(1,ROWS($A$1:$A$118)),1) -> 5,6,7,8 | D5: =INDEX('10'!$A$1:$A$84,RANDBETWEEN(1,ROWS('10'!$A$1:$A$84)),1) -> Beautiful Life | F5: =INDEX('11'!$A$1:$A$22,RANDBETWEEN(1,ROWS('11'!A2:A23)),1) -> Do-bi-di-boy | H5: =INDEX('12-13'!$A$1:$A$22,RANDBETWEEN(1,ROWS('12-13'!$A$1:$A$22)),1) -> Garden State
B6: =INDEX('9'!$A$1:$A$118,RANDBETWEEN(1,ROWS($A$1:$A$118)),1) -> TechLo | D6: =INDEX('10'!$A$1:$A$84,RANDBETWEEN(1,ROWS('10'!$A$1:$A$84)),1) -> Remember december | F6: =INDEX('11'!$A$1:$A$22,RANDBETWEEN(1,ROWS('11'!A3:A24)),1) -> Engel der Nacht | H6: =INDEX('12-13'!$A$1:$A$22,RANDBETWEEN(1,ROWS('12-13'!$A$1:$A$22)),1) -> Blue Sunshine
B7: =INDEX('9'!$A$1:$A$118,RANDBETWEEN(1,ROWS($A$1:$A$118)),1) -> World of fantasy | D7: =INDEX('10'!$A$1:$A$84,RANDBETWEEN(1,ROWS('10'!$A$1:$A$84)),1) -> I wanna be wild | F7: =INDEX('11'!$A$1:$A$22,RANDBETWEEN(1,ROWS('11'!A4:A25)),1) -> Allez ola ole | H7: =INDEX('12-13'!$A$1:$A$22,RANDBETWEEN(1,ROWS('12-13'!$A$1:$A$22)),1) -> Emerge
B8: =INDEX('9'!$A$1:$A$118,RANDBETWEEN(1,ROWS($A$1:$A$118)),1) -> Lover on the line | D8: =INDEX('10'!$A$1:$A$84,RANDBETWEEN(1,ROWS('10'!$A$1:$A$84)),1) -> King Kong | F8: =INDEX('11'!$A$1:$A$22,RANDBETWEEN(1,ROWS('11'!A5:A26)),1) -> Do-bi-di-boy | H8: =INDEX('12-13'!$A$1:$A$22,RANDBETWEEN(1,ROWS('12-13'!$A$1:$A$22)),1) -> Garden State
B9: =INDEX('9'!$A$1:$A$118,RANDBETWEEN(1,ROWS($A$1:$A$118)),1) -> Lemmings on the run | D9: =INDEX('10'!$A$1:$A$84,RANDBETWEEN(1,ROWS('10'!$A$1:$A$84)),1) -> Calendar Girl | F9: =INDEX('11'!$A$1:$A$22,RANDBETWEEN(1,ROWS('11'!A6:A27)),1) -> Stunt flying
B10: =INDEX('9'!$A$1:$A$118,RANDBETWEEN(1,ROWS($A$1:$A$118)),1) -> You are my dream | D10: =INDEX('10'!$A$1:$A$84,RANDBETWEEN(1,ROWS('10'!$A$1:$A$84)),1) -> Charlene Rock mix | F10: =INDEX('11'!$A$1:$A$22,RANDBETWEEN(1,ROWS('11'!A7:A28)),1) -> Make you freak
B11: =INDEX('9'!$A$1:$A$118,RANDBETWEEN(1,ROWS($A$1:$A$118)),1) -> Turn Away | D11: =INDEX('10'!$A$1:$A$84,RANDBETWEEN(1,ROWS('10'!$A$1:$A$84)),1) -> Xepher | F11: =INDEX('11'!$A$1:$A$22,RANDBETWEEN(1,ROWS('11'!A8:A29)),1) -> Allez ola ole
B12: =INDEX('9'!$A$1:$A$118,RANDBETWEEN(1,ROWS($A$1:$A$118)),1) -> Dare to be stupid | D12: =INDEX('10'!$A$1:$A$84,RANDBETWEEN(1,ROWS('10'!$A$1:$A$84)),1) -> Mr Saxobeat | F12: =INDEX('11'!$A$1:$A$22,RANDBETWEEN(1,ROWS('11'!A9:A30)),1) -> Mister Brilliant | J12: 1
B13: =INDEX('9'!$A$1:$A$118,RANDBETWEEN(1,ROWS($A$1:$A$118)),1) -> Futuristic Vision | D13: =INDEX('10'!$A$1:$A$84,RANDBETWEEN(1,ROWS('10'!$A$1:$A$84)),1) -> Mr Saxobeat | F13: =INDEX('11'!$A$1:$A$22,RANDBETWEEN(1,ROWS('11'!A10:A31)),1) -> New Face
B14: =INDEX('9'!$A$1:$A$118,RANDBETWEEN(1,ROWS($A$1:$A$118)),1) -> En mon coeur | D14: =INDEX('10'!$A$1:$A$84,RANDBETWEEN(1,ROWS('10'!$A$1:$A$84)),1) -> Run with us
B15: =INDEX('9'!$A$1:$A$118,RANDBETWEEN(1,ROWS($A$1:$A$118)),1) -> Crazy
B16: =INDEX('9'!$A$1:$A$118,RANDBETWEEN(1,ROWS($A$1:$A$118)),1) -> Save the last dance for me | D16: =INDEX('10'!$A$1:$A$84,RANDBETWEEN(1,ROWS('10'!$A$1:$A$84)),1) -> Uhn Tiss
B17: =INDEX('9'!$A$1:$A$118,RANDBETWEEN(1,ROWS($A$1:$A$118)),1) -> Solina | D17: =INDEX('10'!$A$1:$A$84,RANDBETWEEN(1,ROWS('10'!$A$1:$A$84)),1) -> Tricky Disco
B18: =INDEX('9'!$A$1:$A$118,RANDBETWEEN(1,ROWS($A$1:$A$118)),1) -> Centerfold | D18: =INDEX('10'!$A$1:$A$84,RANDBETWEEN(1,ROWS('10'!$A$1:$A$84)),1) -> Lets go outside
B19: =INDEX('9'!$A$1:$A$118,RANDBETWEEN(1,ROWS($A$1:$A$118)),1) -> Heard that sound | D19: =INDEX('10'!$A$1:$A$84,RANDBETWEEN(1,ROWS('10'!$A$1:$A$84)),1) -> Run with us | F19: =25+0.6*(88-25)-1 -> 61.8
B20: =INDEX('9'!$A$1:$A$118,RANDBETWEEN(1,ROWS($A$1:$A$118)),1) -> Fly away | D20: =INDEX('10'!$A$1:$A$84,RANDBETWEEN(1,ROWS('10'!$A$1:$A$84)),1) -> This is the way
B21: =INDEX('9'!$A$1:$A$118,RANDBETWEEN(1,ROWS($A$1:$A$118)),1) -> Solina | D21: =INDEX('10'!$A$1:$A$84,RANDBETWEEN(1,ROWS('10'!$A$1:$A$84)),1) -> Fun-Loving spirit | F21: =141*0 -> 0
B22: =INDEX('9'!$A$1:$A$118,RANDBETWEEN(1,ROWS($A$1:$A$118)),1) -> Diddily Doo | D22: =INDEX('10'!$A$1:$A$84,RANDBETWEEN(1,ROWS('10'!$A$1:$A$84)),1) -> Ninjyari Bang Bang
B23: =INDEX('9'!$A$1:$A$118,RANDBETWEEN(1,ROWS($A$1:$A$118)),1) -> Centerfold | D23: =INDEX('10'!$A$1:$A$84,RANDBETWEEN(1,ROWS('10'!$A$1:$A$84)),1) -> Cosmic Cowgirl
B24: =INDEX('9'!$A$1:$A$118,RANDBETWEEN(1,ROWS($A$1:$A$118)),1) -> Secret | D24: =INDEX('10'!$A$1:$A$84,RANDBETWEEN(1,ROWS('10'!$A$1:$A$84)),1) -> Story
B25: =INDEX('9'!$A$1:$A$118,RANDBETWEEN(1,ROWS($A$1:$A$118)),1) -> Coming out | D25: =INDEX('10'!$A$1:$A$84,RANDBETWEEN(1,ROWS('10'!$A$1:$A$84)),1) -> Monty on the run
H26: bend your mind
H27: girls generation hittar inte (10)
F28: =RANDBETWEEN(1,15) -> 3 | H28: dota hittar inte på titel
H29: fasten your seatbelts bort

Sheet Karaoke
A1: K stamina test resultat
A3: 43785 | B3: 96.7
A4: 43788 | B4: 95.26
A5: 43868 | B5: 98.38
H6: =RANDBETWEEN(1,3) -> 1
D7: måndag | E7: Organisk kemi
D8: tisdag | E8: Biokemi | K8: =101/3.6 -> 28.055556
D9: onsdag | E9: Kemisk jämvikt
E15: Person | F15: =RANDBETWEEN(1,4) -> 1
E16: Låt | F16: =RANDBETWEEN(1,10) -> 6
E18: Stöd | F18: =RANDBETWEEN(1,4) -> 1

Sheet Englas schema
C3: Roligt | F3: Nyttiga | I3: Saker tillsammans | L3: Rörelse | N3: Slump
C4: Dansmattelåt | D4: 4 | E4: =RAND()*D4 -> 0.21217419 | F4: Repetition Kemi 2 | G4: 4 | H4: =RAND()*G4 -> 2.8365704 | I4: Åker i Skåne | J4: 5 | K4: =RAND()*J4 -> 0.65793756 | L4: Går promenad i Bjärrred | M4: 7 | N4: =RAND()*M4 -> 4.6390532
C5: Koreanska | D5: 10 | E5: =RAND()*D5 -> 7.4746327 | F5: Fysik 2-video | G5: 7 | H5: =RAND()*G5 -> 2.9731917 | I5: Bada | J5: 5 | K5: =RAND()*J5 -> 0.75044018 | L5: Buss + promenad | M5: 3 | N5: =RAND()*M5 -> 1.3077868
C6: Karaoke | D6: 10 | E6: =RAND()*D6 -> 5.7328257 | F6: Fysik 2-uppgifter | G6: 7 | H6: =RAND()*G6 -> 5.3246266
C7: Programmering | D7: 4 | E7: =RAND()*D7 -> 2.4465579 | F7: Fint i rummet | G7: 5 | H7: =RAND()*G7 -> 0.90997686
C8: Teckna | D8: 6 | E8: =RAND()*D8 -> 3.7977367 | F8: Fiol extra | G8: 6 | H8: =RAND()*G8 -> 5.7354751
C9: Läsa | D9: 6 | E9: =RAND()*D9 -> 1.818129 | F9: Matte specialisering | G9: 4 | H9: =RAND()*G9 -> 2.7980702
C10: Origami | D10: 7 | E10: =RAND()*D10 -> 2.8030691 | F10: Kolla sångpedagog | G10: 5 | H10: =RAND()*G10 -> 3.5763856
C11: Dansa | D11: 5 | E11: =RAND()*D11 -> 1.2408852 | F11: Fixa med bandet | G11: 3 | H11: =RAND()*G11 -> 2.9299504
C12: Kuben | D12: 3 | E12: =RAND()*D12 -> 2.4394253
C13: Bas Rocksmith | D13: 7 | E13: =RAND()*D13 -> 4.3879695
C14: Piano Udemy | D14: 5 | E14: =RAND()*D14 -> 3.5331404
C15: Ritkurs Udemy | D15: 5 | E15: =RAND()*D15 -> 1.9492619
C16: Videoredigering | D16: 10 | E16: =RAND()*D16 -> 0.53641261
J18: Ordning lägga in | L18: =RANDBETWEEN(1,7) -> 4
I19: 35 pass | J19: Rörelse
C20: måndag | D20: tisdag | E20: onsdag | F20: torsdag | G20: fredag | J20: ev träning
A21: 9 | B21: 10 | C21: Frukost | D21: Frukost | E21: Frukost | F21: Frukost | G21: Frukost | J21: ev tillsammans
A22: 10 | B22: 11 | E22: Koreanska | F22: Crossfit | J22: övrigt
A23: 11 | B23: 12 | E23: Fint i rummet | F23: Bas Rocksmith
A24: 12 | B24: 13 | C24: Lunch | D24: Lunch | E24: Lunch | F24: Lunch | G24: Lunch
A25: 13 | B25: 14 | E25: Kort promenad (20 min) | F25: Koreanska
A26: 14 | B26: 15 | E26: Läsa | F26: Fysik 2 uppgifter
A27: 15 | B27: 16 | E27: Origami | F27: Dansa
A28: 16 | B28: 17 | E28: Repetition Kemi 2 | F28: Fiol extra
A29: 17 | B29: 18 | C29: Lappen | D29: Lappen | E29: Lappen | F29: Lappen | G29: Lappen
A30: 18 | B30: 19.5 | E30: Löpning 5 km | F30: Promenad Bjärred

Sheet Blad1
C2: Slumpa artärer ben
A3: a ilịaca communis | B3: =RAND() -> 0.65817338 | C3: {=INDEX($A$3:$A$19,RANK(B3,$B$3:$B$19))} -> a profunda fẹmoris
A4: a ilịaca interna | B4: =RAND() -> 0.99498276 | C4: {=INDEX($A$3:$A$19,RANK(B4,$B$3:$B$19))} -> a ilịaca communis
A5: a glutẹa superior | B5: =RAND() -> 0.34266354 | C5: {=INDEX($A$3:$A$19,RANK(B5,$B$3:$B$19))} -> a fibularis (a peronea)
A6: a obturatoria | B6: =RAND() -> 0.83624391 | C6: {=INDEX($A$3:$A$19,RANK(B6,$B$3:$B$19))} -> a obturatoria
A7: a glutẹa inferior | B7: =RAND() -> 0.52899047 | C7: {=INDEX($A$3:$A$19,RANK(B7,$B$3:$B$19))} -> canalis adductorius
A8: a ilịaca externa | B8: =RAND() -> 0.41513457 | C8: {=INDEX($A$3:$A$19,RANK(B8,$B$3:$B$19))} -> a tibialis posterior YA
A9: a femoralis YA | B9: =RAND() -> 0.022752468 | C9: {=INDEX($A$3:$A$19,RANK(B9,$B$3:$B$19))} -> a arcuata
A10: aa pudendae externae | B10: =RAND() -> 0.19786639 | C10: {=INDEX($A$3:$A$19,RANK(B10,$B$3:$B$19))} -> a tibialis anterior
A11: a profunda fẹmoris | B11: =RAND() -> 0.90783508 | C11: {=INDEX($A$3:$A$19,RANK(B11,$B$3:$B$19))} -> a ilịaca interna
A12: a circumflexa fẹmoris lateralis et medialis | B12: =RAND() -> 0.50040392 | C12: {=INDEX($A$3:$A$19,RANK(B12,$B$3:$B$19))} -> a poplịtea YA
A13: canalis adductorius | B13: =RAND() -> 0.051222652 | C13: {=INDEX($A$3:$A$19,RANK(B13,$B$3:$B$19))} -> a dorsalis pedis YA
A14: a poplịtea YA | B14: =RAND() -> 0.70453953 | C14: {=INDEX($A$3:$A$19,RANK(B14,$B$3:$B$19))} -> aa pudendae externae
... A19: a arcuata | B19: =RAND() -> 0.79460717 | C19: {=INDEX($A$3:$A$19,RANK(B19,$B$3:$B$19))} -> a ilịaca externa
B32: =INDEX($A:$A,RANDBETWEEN(1,COUNTA($A:$A)),1)
